Workbook
Name Print_Area: Dashboard!$B$2:$N$60

Sheet Dashboard
B2: RESTAURANTE CHOCLOS Y ASADOS LA FINCA
B3: DASHBOARD GERENCIAL DE COSTOS Y GASTOS - INFORME MENSUAL Y DIARIO SEPTIEMBRE 2026
B5: TOTAL COMPRAS DEL MES | E5: TOTAL COSTOS DIRECTOS (COGS) | I5: TOTAL GASTOS OPERACIONALES (OPEX) | L5: INVENTARIO INICIAL (APERTURA)
B6: 2.1168322e+08 | E6: 1.1635363e+08 | I6: 95329592 | L6: 12243950
B7: COGS: $ 116,353,629.71 | OPEX: $ 95,329,591.71 | E7: 55% de compras del mes | I7: 45% de compras del mes | L7: Stock Inicial (No es categoría)
B9: 1. COSTOS DIRECTOS (COGS: MATERIA PRIMA E INSUMOS) | I9: 2. GASTOS OPERACIONALES Y ADMINISTRATIVOS (OPEX)
B10: Categoría / Insumo | C10: Tipo | D10: N° Compras | E10: Total Mes ($) | F10: % Costos | G10: Prom. Día | I10: Concepto / Categoría | J10: Tipo | K10: N° Pagos | L10: Total Mes ($) | M10: % Gastos | N10: Prom. Día
B11: Carnes y Proteínas | C11: Directo | D11: 179 | E11: 67613773 | F11: 0.58110583 | G11: 2414777.6 | I11: Servicios (Personal y Planta) | J11: Gasto Oper. | K11: 83 | L11: 51133382 | M11: 0.5363852 | N11: 1826192.2
B12: Verduras y Frutas | C12: Directo | D12: 240 | E12: 16098719 | F12: 0.13836026 | G12: 574954.25 | I12: Mantenimiento y Adecuaciones | J12: Gasto Oper. | K12: 17 | L12: 4364978.7 | M12: 0.045788287 | N12: 155892.1
B13: Desechables y Empaques | C13: Directo | D13: 193 | E13: 10394477 | F13: 0.089335223 | G13: 371231.34 | I13: Servicios Públicos (Energía y TV) | J13: Gasto Oper. | K13: 6 | L13: 6232420 | M13: 0.065377601 | N13: 222586.43
B14: Granos y Harinas | C14: Directo | D14: 103 | E14: 7578719 | F14: 0.065135217 | G14: 270668.53 | I14: Otros Gastos Operacionales (Admin y Varios) | J14: Gasto Admin. | K14: 79 | L14: 33598811 | M14: 0.35244891 | N14: 1199957.5
B15: Bebidas y Licores | C15: Directo | D15: 134 | E15: 7593154.9 | F15: 0.065259287 | G15: 271184.11 | I15: SUBTOTAL GASTOS OPERACIONALES | J15: Operativo | K15: 185 | L15: 95329592 | M15: 1 | N15: 3404628.3
B16: Otros Insumos (Abarrotes y Cocina) | C16: Directo | D16: 97 | E16: 7074786.6 | F16: 0.060804176 | G16: 252670.95
B17: SUBTOTAL COSTOS DIRECTOS | C17: Materia Prima | D17: 946 | E17: 1.1635363e+08 | F17: 1 | G17: 4155486.8
B20: RESUMEN CONSOLIDADO: COSTOS DIRECTOS VS GASTOS OPERACIONALES
B21: Costos Directos (COGS) | D21: 946 | E21: 1.1635363e+08 | F21: 0.5496592 | G21: 4155486.8
B22: Gastos Operacionales (OPEX) | D22: 185 | E22: 95329592 | F22: 0.4503408 | G22: 3404628.3
B23: SUBTOTAL COMPRAS DEL MES | D23: 1131 | E23: 2.1168322e+08 | F23: 1 | G23: 7560115.1
B24: (+) Inventario Inicial (Stock Apertura) | D24: 1 | E24: 12243950 | F24: Inversión Inicial | G24: -
B25: TOTAL GENERAL CONSOLIDADO | D25: 1132 | E25: 2.2392717e+08 | F25: 100% Acumulado | G25: -
B26: 3. TOTALIZACIÓN DIARIA: COSTOS Y GASTOS DÍA A DÍA (SEPTIEMBRE 2026)
B27: Día | C27: Costos ($) | D27: Gastos ($) | E27: Total Día ($) | F27: % Costo | G27: % Gasto | H27: Carnes ($) | I27: Verduras ($) | J27: Grano ($) | K27: Bebidas ($) | L27: Desechables ($) | M27: Servicios ($) | N27: N° Compras
B28: 1 | C28: 8325595 | D28: 1051345 | E28: 9376940 | F28: 0.88787973 | G28: 0.11212027 | H28: 6130295 | I28: 132400 | J28: 229750 | K28: 411700 | L28: 1036350 | M28: 130000 | N28: 61
B29: 2 | C29: 1355351 | D29: 30000 | E29: 1385351 | F29: 0.97834484 | G29: 0.021655162 | H29: 528586 | I29: 126240 | J29: 392505 | K29: 162100 | L29: 145920 | M29: 30000 | N29: 26
B30: 3 | C30: 4239440 | D30: 60500 | E30: 4299940 | F30: 0.98593004 | G30: 0.014069964 | H30: 1808790 | I30: 355500 | J30: 1047950 | K30: 970600 | L30: 56600 | M30: 60500 | N30: 40
B31: 4 | C31: 4457519 | D31: 30000 | E31: 4487519 | F31: 0.99331479 | G31: 0.0066852085 | H31: 2218844 | I31: 0 | J31: 256850 | K31: 140975 | L31: 1840850 | M31: 30000 | N31: 60
B32: 5 | C32: 8935184.1 | D32: 0 | E32: 8935184.1 | F32: 1 | G32: 0 | H32: 7713980 | I32: 524200 | J32: 247500 | K32: 386504.07 | L32: 63000 | M32: 0 | N32: 37
B33: 6 | C33: 434000 | D33: 90000 | E33: 524000 | F33: 0.82824427 | G33: 0.17175573 | H33: 0 | I33: 285000 | J33: 0 | K33: 0 | L33: 149000 | M33: 90000 | N33: 7
B34: 7 | C34: 2376803 | D34: 970900 | E34: 3347703 | F34: 0.70998025 | G34: 0.29001975 | H34: 2135215 | I34: 124155 | J34: 0 | K34: 73000 | L34: 29433 | M34: 970900 | N34: 29
B35: 8 | C35: 3875920 | D35: 762810.71 | E35: 4638730.7 | F35: 0.83555616 | G35: 0.16444384 | H35: 966050 | I35: 1392220 | J35: 389300 | K35: 29000 | L35: 1069350 | M35: 578112 | N35: 87
B36: 9 | C36: 11460335 | D36: 2763902 | E36: 14224237 | F36: 0.80569067 | G36: 0.19430933 | H36: 5707282 | I36: 793450 | J36: 1214910 | K36: 1723770 | L36: 1887973 | M36: 2280870 | N36: 80
B37: 10 | C37: 3218466 | D37: 464000 | E37: 3682466 | F37: 0.87399748 | G37: 0.12600252 | H37: 1387295 | I37: 208000 | J37: 441200 | K37: 918471 | L37: 263500 | M37: 464000 | N37: 45
B38: 11 | C38: 9568706 | D38: 47019700 | E38: 56588406 | F38: 0.16909305 | G38: 0.83090695 | H38: 4088560 | I38: 2802750 | J38: 1523150 | K38: 34000 | L38: 535300 | M38: 45390000 | N38: 92
B39: 12 | C39: 10515730 | D39: 1489300 | E39: 12005030 | F39: 0.87594367 | G39: 0.12405633 | H39: 7776020 | I39: 937770 | J39: 0 | K39: 83000 | L39: 0 | M39: 750000 | N39: 56
... B57: 30 | C57: 0 | D57: 0 | E57: 0 | F57: 0 | G57: 0 | H57: 0 | I57: 0 | J57: 0 | K57: 0 | L57: 0 | M57: 0 | N57: 0
B58: TOTAL MES | C58: 1.1635363e+08 | D58: 95329592 | E58: 2.1168322e+08 | F58: 0.5496592 | G58: 0.4503408 | H58: 67613773 | I58: 16098719 | J58: 7578719 | K58: 7593154.9 | L58: 10394477 | M58: 51133382 | N58: 1131
B59: PROMEDIO DIARIO | C59: 4155486.8 | D59: 3404628.3 | E59: 7560115.1 | F59: 0.5496592 | G59: 0.4503408 | H59: 2414777.6 | I59: 574954.25 | J59: 270668.53 | K59: 271184.11 | L59: 371231.34 | M59: 1826192.2 | N59: 40.392857
B60: MÁXIMO DIARIO (PICO) | C60: 11460335 | D60: 47019700 | E60: 56588406 | F60: - | G60: - | H60: 7776020 | I60: 3068320 | J60: 1523150 | K60: 1723770 | L60: 3115501.4 | M60: 45390000 | N60: 92
B61: MÍNIMO DIARIO | C61: 0 | D61: 0 | E61: 0 | F61: - | G61: - | H61: 0 | I61: 0 | J61: 0 | K61: 0 | L61: 0 | M61: 0 | N61: 0

Sheet Dashboard Ventas
B2: DASHBOARD EJECUTIVO DE VENTAS - SEPTIEMBRE 2026
B3: Restaurante Choclos y Asados La Finca - Seguimiento diario de facturación, volumen, mezcla de productos y rentabilidad
B5: TOTAL FACTURADO (GRAN TOTAL) | E5: VENTA NETA TOTAL (BASE) | G5: IMPOCONSUMO (8%) | I5: DESCUENTOS OTORGADOS | K5: TOTAL PLATOS / UNID. VENDIDAS | M5: PROMEDIO VENTA DIARIA (20 DÍAS) | O5: DÍA PICO FACTURACIÓN
B6: 174371548 | E6: 161455142 | G6: 12916408 | I6: 109958 | K6: 9362 | M6: 8718577.4 | O6: Día 6 ($20.262.800)
B9: 1. SEGUIMIENTO DIARIO DE VENTAS - SEPTIEMBRE 2026 | K9: 2. PARTICIPACIÓN Y FACTURACIÓN POR CATEGORÍA
B10: Día | C10: Fecha | D10: Platos / Unid. | E10: Venta Neta ($) | F10: Impoconsumo ($) | G10: Gran Total ($) | H10: Ticket / Ítem | I10: % Mes | K10: Categoría de Venta | L10: Unid. Vendidas | M10: Venta Neta ($) | N10: Gran Total ($) | O10: Ticket / Ítem | P10: % Facturación
B11: 1 | C11: 01/09/2026 | D11: 411 | E11: 6282219 | F11: 502578 | G11: 6784797 | H11: 16508.022 | I11: 0.03891 | K11: Platos Fuertes / Carnes | L11: 2737 | M11: 78987200 | N11: 85306163 | O11: 31167.761 | P11: 0.48922066
B12: 2 | C12: 02/09/2026 | D12: 374 | E12: 5447496 | F12: 435805 | G12: 5883301 | H12: 15730.751 | I12: 0.033740029 | K12: Especialidades Típicas | L12: 2170 | M12: 46528029 | N12: 50250270 | O12: 23156.806 | P12: 0.2881793
B13: 3 | C13: 03/09/2026 | D13: 408 | E13: 5692967 | F13: 455433 | G13: 6148400 | H13: 15069.608 | I13: 0.03526034 | K13: Bebidas | L13: 2196 | M13: 15049167 | N13: 16253094 | O13: 7401.2268 | P13: 0.093209553
B14: 4 | C14: 04/09/2026 | D14: 400 | E14: 5913241 | F14: 473060 | G14: 6386301 | H14: 15965.753 | I14: 0.036624673 | K14: Pescados y Mariscos | L14: 350 | M14: 13269959 | N14: 14331561 | O14: 40947.317 | P14: 0.082189791
B15: 5 | C15: 05/09/2026 | D15: 519 | E15: 10334818 | F15: 826782 | G15: 11161600 | H15: 21505.973 | I15: 0.064010443 | K15: Acompañamientos y Adicionales | L15: 1154 | M15: 5645737 | N15: 6097406 | O15: 5283.714 | P15: 0.034967895
B16: 6 | C16: 06/09/2026 | D16: 842 | E16: 18761854 | F16: 1500947 | G16: 20262801 | H16: 24065.084 | I16: 0.11620474 | K16: Sopas y Entradas | L16: 388 | M16: 1635341 | N16: 1766168 | O16: 4551.9794 | P16: 0.010128763
B17: 7 | C17: 07/09/2026 | D17: 349 | E17: 5144910 | F17: 411590 | G17: 5556500 | H17: 15921.203 | I17: 0.031865864 | K17: Otros / Empaques | L17: 367 | M17: 339709 | N17: 366886 | O17: 999.68937 | P17: 0.0021040474
B18: 8 | C18: 08/09/2026 | D18: 402 | E18: 5927405 | F18: 474199 | G18: 6401604 | H18: 15924.388 | I18: 0.036712434 | K18: TOTAL CATEGORÍAS | L18: 9362 | M18: 161455142 | N18: 174371548 | O18: 18625.459 | P18: 1
B19: 9 | C19: 09/09/2026 | D19: 401 | E19: 6138790 | F19: 491108 | G19: 6629898 | H19: 16533.411 | I19: 0.038021673
B20: 10 | C20: 10/09/2026 | D20: 418 | E20: 6117773 | F20: 489425 | G20: 6607198 | H20: 15806.694 | I20: 0.037891491
B21: 11 | C21: 11/09/2026 | D21: 390 | E21: 5473329 | F21: 437870 | G21: 5911199 | H21: 15156.921 | I21: 0.03390002 | K21: 3. TOP 20 PRODUCTOS MÁS VENDIDOS (RANKING DE FACTURACIÓN)
B22: 12 | C22: 12/09/2026 | D22: 487 | E22: 9342039 | F22: 747361 | G22: 10089400 | H22: 20717.454 | I22: 0.057861504 | K22: Rank | L22: Código | M22: Producto | N22: Categoría | O22: Unid. Vendidas | P22: Gran Total ($) | Q22: % Venta Total
B23: 13 | C23: 13/09/2026 | D23: 727 | E23: 15770930 | F23: 1261670 | G23: 17032600 | H23: 23428.611 | I23: 0.097679927 | K23: #1 | L23: 119 | M23: Paisa especial | N23: Especialidades Típicas | O23: 231 | P23: 11088000 | Q23: 0.063588356
B24: 14 | C24: 14/09/2026 | D24: 310 | E24: 4323242 | F24: 345858 | G24: 4669100 | H24: 15061.613 | I24: 0.026776731 | K24: #2 | L24: 233 | M24: Frijolada chicha jun | N24: Especialidades Típicas | O24: 462 | P24: 9268833 | Q24: 0.05315565
B25: 15 | C25: 15/09/2026 | D25: 420 | E25: 6091664 | F25: 487336 | G25: 6579000 | H25: 15664.286 | I25: 0.037729779 | K25: #3 | L25: 117 | M25: Sobre domingo | N25: Platos Fuertes / Carnes | O25: 143 | P25: 6435000 | Q25: 0.036903956
B26: 16 | C26: 16/09/2026 | D26: 359 | E26: 4652685 | F26: 372215 | G26: 5024900 | H26: 13996.936 | I26: 0.028817201 | K26: #4 | L26: 93 | M26: Paisa economico | N26: Especialidades Típicas | O26: 271 | P26: 5958334 | Q26: 0.034170334
B27: 17 | C27: 17/09/2026 | D27: 403 | E27: 5916159 | F27: 473292 | G27: 6389450 | H27: 15854.715 | I27: 0.036642733 | K27: #5 | L27: 118 | M27: Lengua domingo | N27: Platos Fuertes / Carnes | O27: 131 | P27: 5895000 | Q27: 0.033807121
B28: 18 | C28: 18/09/2026 | D28: 380 | E28: 5661944 | F28: 452956 | G28: 6114899 | H28: 16091.839 | I28: 0.035068215 | K28: #6 | L28: 113 | M28: Tamal | N28: Especialidades Típicas | O28: 219 | P28: 5256000 | Q28: 0.030142532
B29: 19 | C29: 19/09/2026 | D29: 521 | E29: 10599814 | F29: 847986 | G29: 11447800 | H29: 21972.745 | I29: 0.065651766 | K29: #7 | L29: 88 | M29: Junior gallina | N29: Platos Fuertes / Carnes | O29: 141 | P29: 5005500 | Q29: 0.028705945
B30: 20 | C30: 20/09/2026 | D30: 841 | E30: 17861863 | F30: 1428937 | G30: 19290800 | H30: 22937.931 | I30: 0.11063043 | K30: #8 | L30: 215 | M30: Super de cerdo | N30: Platos Fuertes / Carnes | O30: 120 | P30: 4844500 | Q30: 0.027782629
B31: 21 | C31: 21/09/2026 | D31: 0 | E31: 0 | F31: 0 | G31: 0 | H31: 0 | I31: 0 | K31: #9 | L31: 44 | M31: Costilla c san luis | N31: Platos Fuertes / Carnes | O31: 150 | P31: 4575000 | Q31: 0.026237079
B32: 22 | C32: 22/09/2026 | D32: 0 | E32: 0 | F32: 0 | G32: 0 | H32: 0 | I32: 0 | K32: #10 | L32: 223 | M32: Promo cazuela | N32: Platos Fuertes / Carnes | O32: 56 | P32: 4200000 | Q32: 0.024086498
B33: 23 | C33: 23/09/2026 | D33: 0 | E33: 0 | F33: 0 | G33: 0 | H33: 0 | I33: 0 | K33: #11 | L33: 109 | M33: Limonada natural 1l | N33: Bebidas | O33: 283 | P33: 3962001 | Q33: 0.022721602
B34: 24 | C34: 24/09/2026 | D34: 0 | E34: 0 | F34: 0 | G34: 0 | H34: 0 | I34: 0 | K34: #12 | L34: 87 | M34: Cazuela frijol | N34: Especialidades Típicas | O34: 94 | P34: 3807000 | Q34: 0.02183269
... B40: 30 | C40: 30/09/2026 | D40: 0 | E40: 0 | F40: 0 | G40: 0 | H40: 0 | I40: 0 | K40: #18 | L40: 104 | M40: Bandeja sola | N40: Especialidades Típicas | O40: 162 | P40: 2796170 | Q40: 0.016035701
B41: TOTAL MES (DÍAS 1-30) | D41: 9362 | E41: 161455142 | F41: 12916408 | G41: 174371548 | H41: 18625.459 | I41: 1 | K41: #19 | L41: 41 | M41: Churrasco 400 gr apr | N41: Platos Fuertes / Carnes | O41: 51 | P41: 2703000 | Q41: 0.015501382
B42: PROMEDIO DIARIO | D42: 468.1 | E42: 8072757.1 | F42: 645820.4 | G42: 8718577.4 | H42: 18625.459 | I42: - | K42: #20 | L42: 214 | M42: Super de pollo | N42: Platos Fuertes / Carnes | O42: 65 | P42: 2632500 | Q42: 0.015097073
B43: MÁXIMO DIARIO (PICO) | D43: 842 | E43: 18761854 | F43: 1500947 | G43: 20262801 | H43: - | I43: - | K43: SUBTOTAL TOP 20 PRODUCTOS | O43: 3129 | P43: 94583770 | Q43: 0.54242662

Sheet Dashboard Carnes
B2: DASHBOARD Y SEGUIMIENTO DE CARNES - SEPTIEMBRE 2026
B3: Control analítico de cortes, kilogramos comprados, costos unitarios y participación de gasto
B5: TOTAL INVERSIÓN CARNES | D5: TOTAL KILOGRAMOS | F5: COSTO PROM. / KG | G5: N° COMPRAS | H5: % TOTAL RESTAURANTE
B6: 50250945 | D6: 2265.065 | F6: 22185.211 | G6: 133 | H6: 0.29509801
B8: 1. SEGUIMIENTO DIARIO DE COMPRAS DE CARNE | I8: 2. SEGUIMIENTO DETALLADO DÍA A DÍA - REGISTRO CRONOLÓGICO DE COMPRAS DE CARNES
B9: Día | C9: Total Comprado ($) | D9: Kilogramos (Kg) | E9: Costo Prom. ($/Kg) | F9: % del Mes | G9: N° Compras | I9: Día | J9: N° Comprobante / Factura | K9: Ítem / Corte (Nombre Exacto) | L9: Descripción Original / Proveedor | M9: Cantidad (kg) | N9: Costo Unitario | O9: Vr. Total Compra
B10: 1 | C10: 6130295 | D10: 277.28 | E10: 22108.681 | F10: 0.090666365 | G10: 13 | I10: 1 | J10: 01FZ70896 | K10: Pezuña | L10: PEZUÑA CERDO A GRANEL (Supertiendas Cañaveral - 01FZ70896) | M10: 4.755 | N10: 7900 | O10: ='Detalle Compras Septiembre 2026'!G2 -> 37565
B11: 2 | C11: 528586 | D11: 47.234 | E11: 11190.795 | F11: 0.0078177267 | G11: 4 | I11: 1 | J11: 01FZ70896 | K11: Pezuña | L11: PEZUÑA CERDO A GRANEL (Supertiendas Cañaveral - 01FZ70896) | M11: 3.365 | N11: 8915.3 | O11: ='Detalle Compras Septiembre 2026'!G3 -> 30000
B12: 3 | C12: 1808790 | D12: 65.46 | E12: 27631.989 | F12: 0.026751798 | G12: 9 | I12: 1 | J12: FAC-188 | K12: Bagre de mar | L12: BAGRE DE MAR (Gabriel Ramirez Cubillos - FAC-188) | M12: 20 | N12: 16500 | O12: ='Detalle Compras Septiembre 2026'!G7 -> 330000
B13: 4 | C13: 2218844 | D13: 106.76 | E13: 20783.477 | F13: 0.03281645 | G13: 8 | I13: 1 | J13: FAC-916 | K13: Filete de pollo x 120 | L13: Filete pollo 110g (Alexis Valencia - Factura 916) | M13: 4.58 | N13: 18500 | O13: ='Detalle Compras Septiembre 2026'!G8 -> 84730
B14: 5 | C14: 7713980 | D14: 316.15 | E14: 24399.747 | F14: 0.11408889 | G14: 9 | I14: 1 | J14: FAC-916 | K14: Filete de pollo x 350 | L14: Filete pollo 350g (Alexis Valencia - Factura 916) | M14: 15.1 | N14: 18500 | O14: ='Detalle Compras Septiembre 2026'!G9 -> 279350
B15: 6 | C15: 0 | D15: 0 | E15: 0 | F15: 0 | G15: 0 | I15: 1 | J15: FVE-121 | K15: Salmon | L15: Filete de Salmon Grande (Frio Sabor FVE-121) | M15: 9.87 | N15: 55000 | O15: ='Detalle Compras Septiembre 2026'!G10 -> 542850
B16: 7 | C16: 2135215 | D16: 100.007 | E16: 21350.656 | F16: 0.031579587 | G16: 9 | I16: 1 | J16: FVE-121 | K16: Tilapia y truchas | L16: Tilapia Roja (Frio Sabor FVE-121) | M16: 19.81 | N16: 18000 | O16: ='Detalle Compras Septiembre 2026'!G11 -> 356580
B17: 8 | C17: 966050 | D17: 67.25 | E17: 14365.056 | F17: 0.014287769 | G17: 11 | I17: 1 | J17: RCM-01-Sep-2026 | K17: Tilapia y truchas | L17: 6 lbs cabeza Tilapia (Recibo Caja Menor 01-Sep-2026) | M17: 6 | N17: 3666.67 | O17: ='Detalle Compras Septiembre 2026'!G17 -> 22000
B18: 9 | C18: 5707282 | D18: 325.94 | E18: 17510.223 | F18: 0.084410051 | G18: 12 | I18: 1 | J18: YP24140 | K18: Costilla de cerdo especial | L18: COSTILLA DE CERDO IBP 244M (Carnes Los Monos - YP24140) | M18: 28.6 | N18: 14900 | O18: ='Detalle Compras Septiembre 2026'!G23 -> 426140
B19: 10 | C19: 1387295 | D19: 115.505 | E19: 12010.692 | F19: 0.020517935 | G19: 7 | I19: 1 | J19: YP24140 | K19: Lengua de res | L19: LENGUA DE RES IMP X KL (Carnes Los Monos - YP24140) | M19: 27.65 | N19: 23900 | O19: ='Detalle Compras Septiembre 2026'!G24 -> 660835
B20: 11 | C20: 4088560 | D20: 68.97 | E20: 59280.267 | F20: 0.060469337 | G20: 9 | I20: 1 | J20: YP24140 | K20: Sobaco | L20: SOBACO (Carnes Los Monos - YP24140) | M20: 28.7 | N20: 25900 | O20: ='Detalle Compras Septiembre 2026'!G25 -> 743330
B21: 12 | C21: 7776020 | D21: 297.35 | E21: 26151.068 | F21: 0.11500645 | G21: 13 | I21: 1 | J21: YP24140 | K21: Sobrebarriga delgada | L21: SOBREBARRIGA DELGADA (Carnes Los Monos - YP24140) | M21: 18.5 | N21: 34500 | O21: ='Detalle Compras Septiembre 2026'!G26 -> 638250
B22: 13 | C22: 866150.02 | D22: 86.9 | E22: 9967.2039 | F22: 0.01281026 | G22: 6 | I22: 1 | J22: YP24152 | K22: Tocino barril | L22: TOCINETA BARRIL (Carnes Los Monos - YP24152) | M22: 90.35 | N22: 21900 | O22: ='Detalle Compras Septiembre 2026'!G27 -> 1978665
B23: 14 | C23: 2403203.8 | D23: 112.894 | E23: 21287.259 | F23: 0.03554311 | G23: 7 | I23: SUBTOTAL DÍA 1 (13 compras) | M23: =SUM(M10:M22) -> 277.28 | N23: =IF(M23>0, O23/M23, 0) -> 22108.681 | O23: =SUM(O10:O22) -> 6130295
B24: 15 | C24: 234700 | D24: 2 | E24: 117350 | F24: 0.0034711863 | G24: 2 | I24: 2 | J24: FAC-917 | K24: Pernil de pollo | L24: Pernil pollo campo (Alexis Valencia - Factura 917) | M24: 34.7 | N24: 7500 | O24: ='Detalle Compras Septiembre 2026'!G46 -> 260250
B25: 16 | C25: 1322675 | D25: 31.905 | E25: 41456.668 | F25: 0.019562213 | G25: 5 | I25: 2 | J25: DESP-0444 | K25: Higado | L25: HIGADO DE RES (Poblado Despacho 0444) | M25: 5 | N25: 21500 | O25: ='Detalle Compras Septiembre 2026'!G47 -> 107500
B26: 17 | C26: 5398439 | D26: 261.18 | E26: 20669.42 | F26: 0.079842298 | G26: 12 | I26: 2 | J26: 03FH104321 | K26: Alas de pollo | L26: ALAS POLLO MACPOLLO CONGELADO (Supertiendas Cañaveral - 03FH104321) | M26: 2.77 | N26: 19900 | O26: ='Detalle Compras Septiembre 2026'!G51 -> 55123
B27: 18 | C27: 1106000 | D27: 65 | E27: 17015.385 | F27: 0.016357614 | G27: 2 | I27: 2 | J27: 03FH104321 | K27: Alas de pollo | L27: ALAS POLLO MACPOLLO CONGELADO (Supertiendas Cañaveral - 03FH104321) | M27: 4.764 | N27: 22190 | O27: ='Detalle Compras Septiembre 2026'!G52 -> 105713
B28: 19 | C28: 5243054 | D28: 18970.47 | E28: 276.37976 | F28: 0.077544172 | G28: 7 | I28: SUBTOTAL DÍA 2 (4 compras) | M28: =SUM(M24:M27) -> 47.234 | N28: =IF(M28>0, O28/M28, 0) -> 11190.795 | O28: =SUM(O24:O27) -> 528586
B29: 20 | C29: 0 | D29: 0 | E29: 0 | F29: 0 | G29: 0 | I29: 3 | J29: FE01576 | K29: Caderita | L29: CADERITA DE RES (MYC - FE01576) | M29: 5.96 | N29: 34000 | O29: ='Detalle Compras Septiembre 2026'!G80 -> 202640
B30: 21 | C30: 0 | D30: 0 | E30: 0 | F30: 0 | G30: 0 | I30: 3 | J30: FE01576 | K30: Callo | L30: CALLO DE RES (MYC - FE01576) | M30: 7 | N30: 20000 | O30: ='Detalle Compras Septiembre 2026'!G81 -> 140000
B31: 22 | C31: 2693444 | D31: 140.194 | E31: 19212.263 | F31: 0.03983573 | G31: 12 | I31: 3 | J31: FE01570 | K31: Higado | L31: HIGADO DE RES (MYC - FE01570) | M31: 5.8 | N31: 22000 | O31: ='Detalle Compras Septiembre 2026'!G82 -> 127600
B32: 23 | C32: 3368820 | D32: 143.155 | E32: 23532.674 | F32: 0.049824464 | G32: 5 | I32: 3 | J32: FE01570 | K32: Lomo viche | L32: LOMO VICHE ESPECIAL DE RES (MYC - FE01570) | M32: 7.35 | N32: 54000 | O32: ='Detalle Compras Septiembre 2026'!G83 -> 396900
B33: 24 | C33: 168188 | D33: 18.432 | E33: 9124.783 | F33: 0.0024874814 | G33: 2 | I33: 3 | J33: FE01569 | K33: Caderita | L33: CADERITA DE RES (MYC - FE01569) | M33: 4.05 | N33: 33000 | O33: ='Detalle Compras Septiembre 2026'!G84 -> 133650
B34: 25 | C34: 2061250 | D34: 103.45 | E34: 19925.085 | F34: 0.030485653 | G34: 8 | I34: 3 | J34: FE01569 | K34: Costilla Especial | L34: COSTILLA ESPECIAL DE RES (MYC - FE01569) | M34: 10.3 | N34: 20000 | O34: ='Detalle Compras Septiembre 2026'!G85 -> 206000
B35: 26 | C35: 1966882 | D35: 17598.63 | E35: 111.76336 | F35: 0.029089961 | G35: 6 | I35: 3 | J35: 0000006666 | K35: Chorizo | L35: CHORIZO COCTELERO 4 PAQ (Carnicos Montero FAC-0000006666) | M35: 4 | N35: 48000 | O35: ='Detalle Compras Septiembre 2026'!G92 -> 192000
B36: 27 | C36: 320050 | D36: 17.3 | E36: 18500 | F36: 0.004733503 | G36: 1 | I36: 3 | J36: 0000006666 | K36: Chorizo | L36: CHORIZO PREMIUM 1 PAQ (Carnicos Montero FAC-0000006666) | M36: 1 | N36: 46000 | O36: ='Detalle Compras Septiembre 2026'!G93 -> 46000
B37: 28 | C37: 0 | D37: 0 | E37: 0 | F37: 0 | G37: 0 | I37: 3 | J37: FE1-49657 | K37: Costilla de cerdo | L37: COSTILLA CERDO ESP CR (BS) X 4 KG (ARMAR ALIMENTOS S.A.S.) | M37: 20 | N37: 18200 | O37: ='Detalle Compras Septiembre 2026'!G504 -> 364000
B38: 29 | C38: 0 | D38: 0 | E38: 0 | F38: 0 | G38: 0 | I38: SUBTOTAL DÍA 3 (9 compras) | M38: =SUM(M29:M37) -> 65.46 | N38: =IF(M38>0, O38/M38, 0) -> 27631.989 | O38: =SUM(O29:O37) -> 1808790
B39: 30 | C39: 0 | D39: 0 | E39: 0 | F39: 0 | G39: 0 | I39: 4 | J39: FEBF-33 | K39: Lomo de cerdo | L39: LOMO DE CERDO (Fabian Bonilla - FEBF-33) | M39: 26.5 | N39: 19500 | O39: ='Detalle Compras Septiembre 2026'!G142 -> 516750
B40: TOTAL MES | C40: 67613773 | D40: 39339.416 | E40: 1718.7284 | F40: 1 | G40: 179 | I40: 4 | J40: FAC-920 | K40: Filete de pollo x 350 | L40: Filete pollo 350g (Alexis Valencia - Factura 920) | M40: 23.5 | N40: 18500 | O40: ='Detalle Compras Septiembre 2026'!G143 -> 434750
I41: 4 | J41: FAC-8118 | K41: Morcilla | L41: 10 lb Libra de morcilla (La Morcilla Jamundeña Factura 8118) | M41: 10 | N41: 10000 | O41: ='Detalle Compras Septiembre 2026'!G144 -> 100000
I42: 4 | J42: 05FZ91332 | K42: Pechuga macpollo | L42: PECHUGA MACPOLLO BLANCO REFRI MARIN GK (Supertiendas Canaveral 05FZ91332) | M42: 3.095 | N42: 13980 | O42: ='Detalle Compras Septiembre 2026'!G147 -> 43269
I43: 4 | J43: FVE 130 | K43: Tilapia Roja | L43: Tilapia Roja (Gerson Alexander Valencia Angel) | M43: 20.74 | N43: 18000 | O43: ='Detalle Compras Septiembre 2026'!G529 -> 373320
...

Sheet Dashboard Bebidas
B2: DASHBOARD Y SEGUIMIENTO DE BEBIDAS - SEPTIEMBRE 2026
B3: Control analítico exclusivo de bebidas de tomar (cervezas, gaseosas, aguas, hidratantes, maltas)
B5: TOTAL INVERSIÓN BEBIDAS | D5: TOTAL UNIDADES / CAJAS | F5: COSTO PROM. / UND | G5: N° PEDIDOS | H5: % TOTAL RESTAURANTE
B6: 5929256.1 | D6: 1478 | F6: 4011.6753 | G6: 95 | H6: 0.034819478
B8: 1. SEGUIMIENTO DIARIO DE BEBIDAS | I8: 2. SEGUIMIENTO DETALLADO DÍA A DÍA - REGISTRO CRONOLÓGICO DE COMPRAS DE BEBIDAS
B9: Día | C9: Total Comprado ($) | D9: Cantidad (Caj/Und) | E9: Costo Prom. ($) | F9: % del Mes | G9: N° Pedidos | I9: Día | J9: N° Comprobante / Factura | K9: Ítem / Bebida (Nombre Exacto) | L9: Descripción Original (PDF) | M9: Cajas Compradas | N9: Costo Unitario Caja ($) | O9: Unid. x Caja | P9: Total Botellas / Unid. | Q9: Costo Unit. Botella ($) | R9: Vr. Total Compra ($)
B10: 1 | C10: 411700 | D10: 5 | E10: 82340 | F10: 0.054219887 | G10: 4 | I10: 1 | J10: VC242247 | K10: Cerv Stel Artois | L10: CERV.STEL ARTOIS*300ml BOT (Global Liquors VC242247) | M10: 1 | N10: 92200 | O10: 1 | P10: =M10*O10 -> 1 | Q10: =IF(P10>0, R10/P10, 0) -> 92200 | R10: ='Detalle Compras Septiembre 2026'!G18 -> 92200
B11: 2 | C11: 162100 | D11: 4 | E11: 40525 | F11: 0.021348175 | G11: 3 | I11: 1 | J11: VC242247 | K11: Club colombia | L11: CERV.CLUB DOR LATA*330 (Global Liquors VC242247) | M11: 1 | N11: 77500 | O11: 1 | P11: =M11*O11 -> 1 | Q11: =IF(P11>0, R11/P11, 0) -> 77500 | R11: ='Detalle Compras Septiembre 2026'!G19 -> 77500
B12: 3 | C12: 970600 | D12: 360 | E12: 2696.1111 | F12: 0.12782565 | G12: 8 | I12: 1 | J12: VC242247 | K12: Corona | L12: CERV.CORONA*330ml (Global Liquors VC242247) | M12: 1 | N12: 93000 | O12: 1 | P12: =M12*O12 -> 1 | Q12: =IF(P12>0, R12/P12, 0) -> 93000 | R12: ='Detalle Compras Septiembre 2026'!G20 -> 93000
B13: 4 | C13: 140975 | D13: 7 | E13: 20139.286 | F13: 0.018566064 | G13: 2 | I13: 1 | J13: VC242247 | K13: Poker | L13: CERV.POKER*330 LATA (Global Liquors VC242247) | M13: 2 | N13: 74500 | O13: 1 | P13: =M13*O13 -> 2 | Q13: =IF(P13>0, R13/P13, 0) -> 74500 | R13: ='Detalle Compras Septiembre 2026'!G21 -> 149000
B14: 5 | C14: 386504.07 | D14: 4695 | E14: 82.322486 | F14: 0.050901644 | G14: 15 | I14: SUBTOTAL DÍA 1 (4 compras) | M14: =SUM(M10:M13) -> 5 | N14: =IF(M14>0, R14/M14, 0) -> 82340 | O14: - | P14: =SUM(P10:P13) -> 5 | Q14: =IF(P14>0, R14/P14, 0) -> 82340 | R14: =SUM(R10:R13) -> 411700
B15: 6 | C15: 0 | D15: 0 | E15: 0 | F15: 0 | G15: 0 | I15: 2 | J15: VC242401 | K15: Gatorade | L15: BEB.GATORADE*500ml SURT. (Global Liquors - VC242401) | M15: 2 | N15: 39000 | O15: 1 | P15: =M15*O15 -> 2 | Q15: =IF(P15>0, R15/P15, 0) -> 39000 | R15: ='Detalle Compras Septiembre 2026'!G29 -> 78000
B16: 7 | C16: 73000 | D16: 11 | E16: 6636.3636 | F16: 0.0096139221 | G16: 4 | I16: 2 | J16: VC242401 | K16: H2o | L16: AGUA H2O*600ml SURTIDA (Global Liquors VC242401 c/ NC NX8465) | M16: 1 | N16: 32500 | O16: 1 | P16: =M16*O16 -> 1 | Q16: =IF(P16>0, R16/P16, 0) -> 32500 | R16: ='Detalle Compras Septiembre 2026'!G30 -> 32500
B17: 8 | C17: 29000 | D17: 4 | E17: 7250 | F17: 0.0038192293 | G17: 2 | I17: 2 | J17: VC242401 | K17: Vive 100 | L17: BEB.EN.*380 VIVE100 (Global Liquors - VC242401) | M17: 1 | N17: 51600 | O17: 1 | P17: =M17*O17 -> 1 | Q17: =IF(P17>0, R17/P17, 0) -> 51600 | R17: ='Detalle Compras Septiembre 2026'!G31 -> 51600
B18: 9 | C18: 1723770 | D18: 8423 | E18: 204.65036 | F18: 0.22701631 | G18: 26 | I18: SUBTOTAL DÍA 2 (3 compras) | M18: =SUM(M15:M17) -> 4 | N18: =IF(M18>0, R18/M18, 0) -> 40525 | O18: - | P18: =SUM(P15:P17) -> 4 | Q18: =IF(P18>0, R18/P18, 0) -> 40525 | R18: =SUM(R15:R17) -> 162100
B19: 10 | C19: 918471 | D19: 37 | E19: 24823.541 | F19: 0.12096039 | G19: 9 | I19: 3 | J19: FEMSA-3390 | K19: Brisa 600 ml | L19: AGUA BRISA PET 600ML (24) (Coca-Cola FEMSA - 5571323390) | M19: 1 | N19: 32000 | O19: 24 | P19: =M19*O19 -> 24 | Q19: =IF(P19>0, R19/P19, 0) -> 1333.3333 | R19: ='Detalle Compras Septiembre 2026'!G71 -> 32000
B20: 11 | C20: 34000 | D20: 5 | E20: 6800 | F20: 0.0044777171 | G20: 2 | I20: 3 | J20: FEMSA-3390 | K20: Coca cola 1,5 lt pet (12) nvo | L20: COCA COLA 1.5LT PET(12) Nvo (Coca-Cola FEMSA - 5571323390) | M20: 2 | N20: 65000 | O20: 12 | P20: =M20*O20 -> 24 | Q20: =IF(P20>0, R20/P20, 0) -> 5416.6667 | R20: ='Detalle Compras Septiembre 2026'!G72 -> 130000
B21: 12 | C21: 83000 | D21: 4 | E21: 20750 | F21: 0.010930898 | G21: 4 | I21: 3 | J21: FEMSA-3390 | K21: Coca cola zero 1,5 ltrs | L21: COCA COLA ZERO 1.5LT PET(12)KZ (Coca-Cola FEMSA - 5571323390) | M21: 2 | N21: 65000 | O21: 12 | P21: =M21*O21 -> 24 | Q21: =IF(P21>0, R21/P21, 0) -> 5416.6667 | R21: ='Detalle Compras Septiembre 2026'!G73 -> 130000
B22: 13 | C22: 126500 | D22: 78 | E22: 1621.7949 | F22: 0.016659742 | G22: 2 | I22: 3 | J22: FEMSA-3390 | K22: Coca cola zero 400ml pet(12)kz | L22: COCA COLA ZERO 400ML PET(12)KZ (Coca-Cola FEMSA - 5571323390) | M22: 10 | N22: 28800 | O22: 12 | P22: =M22*O22 -> 120 | Q22: =IF(P22>0, R22/P22, 0) -> 2400 | R22: ='Detalle Compras Septiembre 2026'!G74 -> 288000
B23: 14 | C23: 0 | D23: 0 | E23: 0 | F23: 0 | G23: 0 | I23: 3 | J23: FEMSA-3390 | K23: Coca-cola 400 ml pet (24) | L23: COCA-COLA 400ML PET (12) (Coca-Cola FEMSA - 5571323390) | M23: 8 | N23: 30000 | O23: 12 | P23: =M23*O23 -> 96 | Q23: =IF(P23>0, R23/P23, 0) -> 2500 | R23: ='Detalle Compras Septiembre 2026'!G75 -> 240000
B24: 15 | C24: 38436 | D24: 6 | E24: 6406 | F24: 0.0050619275 | G24: 3 | I24: 3 | J24: FEMSA-3389 | K24: Gaseosa 400 ml | L24: QUATRO CHOICE 400ML NR (12) (Coca-Cola FEMSA - 5571323389) | M24: 2 | N24: 25100 | O24: 12 | P24: =M24*O24 -> 24 | Q24: =IF(P24>0, R24/P24, 0) -> 2091.6667 | R24: ='Detalle Compras Septiembre 2026'!G76 -> 50200
B25: 16 | C25: 34000 | D25: 1 | E25: 34000 | F25: 0.0044777171 | G25: 1 | I25: 3 | J25: FEMSA-3389 | K25: Gaseosa 400 ml | L25: PREMIO ROJO FNT 400 ML PET(12) (Coca-Cola FEMSA - 5571323389) | M25: 2 | N25: 25100 | O25: 12 | P25: =M25*O25 -> 24 | Q25: =IF(P25>0, R25/P25, 0) -> 2091.6667 | R25: ='Detalle Compras Septiembre 2026'!G77 -> 50200
B26: 17 | C26: 249000 | D26: 61 | E26: 4081.9672 | F26: 0.032792693 | G26: 3 | I26: 3 | J26: FEMSA-3389 | K26: Gaseosa 400 ml | L26: SPRITE 400 ML NR (12) (Coca-Cola FEMSA - 5571323389) | M26: 2 | N26: 25100 | O26: 12 | P26: =M26*O26 -> 24 | Q26: =IF(P26>0, R26/P26, 0) -> 2091.6667 | R26: ='Detalle Compras Septiembre 2026'!G78 -> 50200
B27: 18 | C27: 548200 | D27: 8 | E27: 68525 | F27: 0.072196604 | G27: 7 | I27: SUBTOTAL DÍA 3 (8 compras) | M27: =SUM(M19:M26) -> 29 | N27: =IF(M27>0, R27/M27, 0) -> 33468.966 | O27: - | P27: =SUM(P19:P26) -> 360 | Q27: =IF(P27>0, R27/P27, 0) -> 2696.1111 | R27: =SUM(R19:R26) -> 970600
B28: 19 | C28: 0 | D28: 0 | E28: 0 | F28: 0 | G28: 0 | I28: 4 | J28: A 1494 | K28: Extracto de Coco Premium 1000 ml | L28: Extrato de coco premium 1000 mL (COL COCO S.A.S.) | M28: 5 | N28: 24395 | O28: 1 | P28: =M28*O28 -> 5 | Q28: =IF(P28>0, R28/P28, 0) -> 24395 | R28: ='Detalle Compras Septiembre 2026'!G528 -> 121975
B29: 20 | C29: 0 | D29: 0 | E29: 0 | F29: 0 | G29: 0 | I29: 4 | J29: NV202395 | K29: Hielo en bloque | L29: BLOQUE MEDIA (INDUSTRIA HIELO EL NEVADO SAS) | M29: 2 | N29: 9500 | O29: 1 | P29: =M29*O29 -> 2 | Q29: =IF(P29>0, R29/P29, 0) -> 9500 | R29: ='Detalle Compras Septiembre 2026'!G568 -> 19000
B30: 21 | C30: 248000 | D30: 1512 | E30: 164.02116 | F30: 0.032660996 | G30: 6 | I30: SUBTOTAL DÍA 4 (2 compras) | M30: =SUM(M28:M29) -> 7 | N30: =IF(M30>0, R30/M30, 0) -> 20139.286 | O30: - | P30: =SUM(P28:P29) -> 7 | Q30: =IF(P30>0, R30/P30, 0) -> 20139.286 | R30: =SUM(R28:R29) -> 140975
B31: 22 | C31: 0 | D31: 0 | E31: 0 | F31: 0 | G31: 0 | I31: 5 | J31: JM07-1019725 | K31: H2OH! Maracuyá 600 ml | L31: MARACUYA H2OH! 600 ML PET X 15 (POSTOBON S.A.) | M31: 5 | N31: 1820.73 | O31: 1 | P31: =M31*O31 -> 5 | Q31: =IF(P31>0, R31/P31, 0) -> 1820.73 | R31: ='Detalle Compras Septiembre 2026'!G512 -> 9103.65
B32: 23 | C32: 0 | D32: 0 | E32: 0 | F32: 0 | G32: 0 | I32: 5 | J32: JM07-1019725 | K32: H2OH! Limoneto 600 ml | L32: LIMONATA H2OH! 600 ML PET X 15 (POSTOBON S.A.) | M32: 5 | N32: 1820.73 | O32: 1 | P32: =M32*O32 -> 5 | Q32: =IF(P32>0, R32/P32, 0) -> 1820.73 | R32: ='Detalle Compras Septiembre 2026'!G513 -> 9103.65
B33: 24 | C33: 285500 | D33: 174 | E33: 1640.8046 | F33: 0.037599654 | G33: 6 | I33: 5 | J33: JM07-1019725 | K33: H2OH! Manzana 600 ml | L33: MANZANA H2OH 600 ML PET X 15 (POSTOBON S.A.) | M33: 5 | N33: 1820.73 | O33: 1 | P33: =M33*O33 -> 5 | Q33: =IF(P33>0, R33/P33, 0) -> 1820.73 | R33: ='Detalle Compras Septiembre 2026'!G514 -> 9103.65
B34: 25 | C34: 672600 | D34: 16 | E34: 42037.5 | F34: 0.088579781 | G34: 16 | I34: 5 | J34: JM07-1019725 | K34: Mr Tea Durazno 500 ml | L34: DURAZNO MR TEA 500 ML PET X 12 (Postobón S.A.) | M34: 6 | N34: 1890.76 | O34: 12 | P34: =M34*O34 -> 72 | Q34: =IF(P34>0, R34/P34, 0) -> 157.56333 | R34: ='Detalle Compras Septiembre 2026'!G515 -> 11344.56
B35: 26 | C35: 457798.87 | D35: 4887 | E35: 93.676871 | F35: 0.060290995 | G35: 11 | I35: 5 | J35: JM07-1019725 | K35: Mr Tea Limón 500 ml | L35: LIMON MR TEA 500 ML PET X 12 (Postobón S.A.) | M35: 6 | N35: 1890.76 | O35: 12 | P35: =M35*O35 -> 72 | Q35: =IF(P35>0, R35/P35, 0) -> 157.56333 | R35: ='Detalle Compras Septiembre 2026'!G516 -> 11344.56
B36: 27 | C36: 0 | D36: 0 | E36: 0 | F36: 0 | G36: 0 | I36: 5 | J36: JM07-1019725 | K36: Postobón Naranja 1.75 L | L36: NARANJA POSTOBON 1.750 ML PET X 12 PM (Postobón S.A.) | M36: 6 | N36: 3151.26 | O36: 12 | P36: =M36*O36 -> 72 | Q36: =IF(P36>0, R36/P36, 0) -> 262.605 | R36: ='Detalle Compras Septiembre 2026'!G517 -> 18907.56
B37: 28 | C37: 0 | D37: 0 | E37: 0 | F37: 0 | G37: 0 | I37: 5 | J37: JM07-1019725 | K37: Postobón Uva 1.75 L | L37: UVA POSTOBON PET 1.750 ML PET X 12 PM (Postobón S.A.) | M37: 6 | N37: 3151.26 | O37: 12 | P37: =M37*O37 -> 72 | Q37: =IF(P37>0, R37/P37, 0) -> 262.605 | R37: ='Detalle Compras Septiembre 2026'!G518 -> 18907.56
B38: 29 | C38: 0 | D38: 0 | E38: 0 | F38: 0 | G38: 0 | I38: 5 | J38: JM07-1019725 | K38: Piña Postobón 350 ml Vidrio | L38: PIÑA NACIONAL 350 ML VIDRIO R X 30 (Postobón S.A.) | M38: 15 | N38: 1450.98 | O38: 30 | P38: =M38*O38 -> 450 | Q38: =IF(P38>0, R38/P38, 0) -> 48.366 | R38: ='Detalle Compras Septiembre 2026'!G519 -> 21764.7
B39: 30 | C39: 0 | D39: 0 | E39: 0 | F39: 0 | G39: 0 | I39: 5 | J39: JM07-1019725 | K39: Colombiana 350 ml Vidrio | L39: COLOMBIANA NACIONAL 350 ML VIDRIO R X 30 (Postobón S.A.) | M39: 15 | N39: 1450.98 | O39: 30 | P39: =M39*O39 -> 450 | Q39: =IF(P39>0, R39/P39, 0) -> 48.366 | R39: ='Detalle Compras Septiembre 2026'!G520 -> 21764.7
B40: TOTAL MES | C40: 7593154.9 | D40: 20298 | E40: 374.0839 | F40: 1 | G40: 134 | I40: 5 | J40: JM07-1019725 | K40: Postobón Uva 350 ml Vidrio | L40: UVA POSTOBON 350 ML VIDRIO R X 30 (Postobón S.A.) | M40: 15 | N40: 1450.98 | O40: 30 | P40: =M40*O40 -> 450 | Q40: =IF(P40>0, R40/P40, 0) -> 48.366 | R40: ='Detalle Compras Septiembre 2026'!G521 -> 21764.7
I41: 5 | J41: JM07-1019725 | K41: Postobón Manzana 350 ml Vidrio | L41: MANZANA POSTOBON 350 ML VIDRIO R X 30 (Postobón S.A.) | M41: 15 | N41: 1450.98 | O41: 30 | P41: =M41*O41 -> 450 | Q41: =IF(P41>0, R41/P41, 0) -> 48.366 | R41: ='Detalle Compras Septiembre 2026'!G522 -> 21764.7
I42: 5 | J42: JM07-1019725 | K42: Postobón Manzana 1.75 L | L42: MANZANA POSTOBON 1.750 ML PET X 12 PM (Postobón S.A.) | M42: 12 | N42: 3151.26 | O42: 12 | P42: =M42*O42 -> 144 | Q42: =IF(P42>0, R42/P42, 0) -> 262.605 | R42: ='Detalle Compras Septiembre 2026'!G523 -> 37815.12
I43: 5 | J43: JM07-1019725 | K43: Colombiana 1.75 L | L43: COLOMBIANA NACIONAL 1.750 ML PET X 12 PM (Postobón S.A.) | M43: 12 | N43: 3151.26 | O43: 12 | P43: =M43*O43 -> 144 | Q43: =IF(P43>0, R43/P43, 0) -> 262.605 | R43: ='Detalle Compras Septiembre 2026'!G524 -> 37815.12
...

Sheet Dashboard Nomina
B2: RESTAURANTE CHOCLOS Y ASADOS LA FINCA
B3: DASHBOARD ANALÍTICO DE NÓMINA, HONORARIOS Y TALENTO HUMANO - SEPTIEMBRE 2026
B5: TOTAL TALENTO HUMANO Y HONORARIOS | E5: NÓMINA FIJA Y SERVICIOS TEMPORALES | I5: HONORARIOS Y GESTIÓN DIRECTIVA | L5: TURNOS OPERATIVOS EN EFECTIVO | O5: Nº PAGOS REGISTRADOS
B6: =$E$27 -> 49772637 | E6: =$E$11+$E$12 -> 39220837 | I6: =$E$13+$E$14+$E$15+$E$16 -> 5944800 | L6: =SUM(E17:E22) -> 3063200 | O6: =$D$27 -> 89
B7: Nómina + Temporales + Honorarios + Turnos + Gestión | E7: 4 Quincenas BBVA + 2 Facturas GIT (Agosto y Sept) | I7: Contadora, Antonio, Arturo, Eliana | L7: Turnos caja menor: salón, cocina y fin de semana | O7: Transacciones personal
B9: 1. RESUMEN EJECUTIVO POR MODALIDAD DE CONTRATACIÓN Y BENEFICIARIO | I9: 2. REGISTRO CRONOLÓGICO Y DETALLADO DÍA A DÍA (DETALLE DE TRANSACCIONES)
B10: Concepto / Beneficiario | C10: Modalidad Contractual | D10: Nº Pagos | E10: Total Mes ($) | F10: % Part. | G10: Promedio Pago ($) | I10: Día | J10: Soporte / Fac | K10: Beneficiario / Personal | L10: Concepto / Modalidad | M10: Descripción Detallada | N10: Vr. Pagado ($) | O10: Fuente / Observaciones
B11: Nómina Bancaria 1ra Quincena (BBVA) | C11: Nómina Quincenal Fija | D11: =COUNTIF('Detalle Compras Septiembre 2026'!$H$569:$H$635, "TR-BBVA-1509") -> 4 | E11: =SUMIF('Detalle Compras Septiembre 2026'!$H$569:$H$635, "TR-BBVA-1509", 'Detalle Compras Septiembre 2026'!$G$569:$G$635) -> 4302852 | F11: =IF($E$27>0, E11/$E$27, 0) -> 0.086450151 | G11: =IF(D11>0, E11/D11, 0) -> 1075713 | I11: 7 | J11: Libro de Caja | K11: Arturo Díaz | L11: Gestión Directiva | M11: Devolución Señor Arturo Principal (Johanna) | N11: ='Detalle Compras Septiembre 2026'!G174 -> 90000 | O11: Efectivo Caja Menor
B12: Servicios Temporales Nómina (GIT) | C12: Temporal / AIU Planta | D12: 3 | E12: ='Detalle Compras Septiembre 2026'!$G$377+'Detalle Compras Septiembre 2026'!$G$642+'Detalle Compras Septiembre 2026'!$G$643 -> 34917985 | F12: =IF($E$27>0, E12/$E$27, 0) -> 0.70154983 | G12: =IF(D12>0, E12/D12, 0) -> 11639328 | I12: 7 | J12: RCM-07-Sep-2026 | K12: Arturo Díaz | L12: Gestión Directiva | M12: Encomienda Arturo (Recibo Caja Menor 07-Sep-2026) | N12: ='Detalle Compras Septiembre 2026'!G185 -> 74000 | O12: Caja Menor
B13: Honorarios Contadora Pública | C13: Honorarios Profesionales | D13: 3 | E13: ='Detalle Compras Septiembre 2026'!$G$374+'Detalle Compras Septiembre 2026'!$G$397+'Detalle Compras Septiembre 2026'!$G$484 -> 2400000 | F13: =IF($E$27>0, E13/$E$27, 0) -> 0.048219266 | G13: =IF(D13>0, E13/D13, 0) -> 800000 | I13: 7 | J13: Libro de Caja | K13: Marleny | L13: Turno Operativo | M13: Turno Marleny Domicilios (Carolina) | N13: ='Detalle Compras Septiembre 2026'!G190 -> 66000 | O13: Efectivo Caja Menor
B14: Gestión y Dirección (Antonio Díaz) | C14: Gestión Directiva / Apoyo | D14: 2 | E14: ='Detalle Compras Septiembre 2026'!$G$344+'Detalle Compras Septiembre 2026'!$G$392 -> 310000 | F14: =IF($E$27>0, E14/$E$27, 0) -> 0.0062283218 | G14: =IF(D14>0, E14/D14, 0) -> 155000 | I14: 7 | J14: Libro de Caja | K14: Jhonatan | L14: Vale Descontable | M14: Crédito Jhonatan Domicilios (Carolina) | N14: ='Detalle Compras Septiembre 2026'!G193 -> 4000 | O14: Anticipo Empleado
B15: Retiros y Encomiendas (Don Arturo) | C15: Retiro Socio / Encomiendas | D15: 6 | E15: ='Detalle Compras Septiembre 2026'!$G$174+'Detalle Compras Septiembre 2026'!$G$185+'Detalle Compras Septiembre 2026'!$G$194+'Detalle Compras Septiembre 2026'!$G$318+'Detalle Compras Septiembre 2026'!$G$692+'Detalle Compras Septiembre 2026'!$G$693 -> 1740800 | F15: =IF($E$27>0, E15/$E$27, 0) -> 0.034975041 | G15: =IF(D15>0, E15/D15, 0) -> 290133.33 | I15: 7 | J15: Libro de Caja | K15: Arturo Díaz | L15: Gestión Directiva | M15: Devolución Señor Arturo Domicilios (Carolina) | N15: ='Detalle Compras Septiembre 2026'!G194 -> 85000 | O15: Salida Caja Menor
B16: Honorarios Operativos (Eliana) | C16: Honorarios / Cuenta Cobro | D16: 2 | E16: ='Detalle Compras Septiembre 2026'!$G$373+'Detalle Compras Septiembre 2026'!$G$687 -> 1494000 | F16: =IF($E$27>0, E16/$E$27, 0) -> 0.030016493 | G16: =IF(D16>0, E16/D16, 0) -> 747000 | I16: 7 | J16: Libro de Caja | K16: Carolina | L16: Transporte Personal | M16: Transporte Carolina Domicilios (Carolina) | N16: ='Detalle Compras Septiembre 2026'!G195 -> 15000 | O16: Transporte Operativo
B17: Turnos de Personal - Marleny | C17: Turno Operativo Salón/Cocina | D17: 11 | E17: ='Detalle Compras Septiembre 2026'!$G$190+'Detalle Compras Septiembre 2026'!$G$253+'Detalle Compras Septiembre 2026'!$G$316+'Detalle Compras Septiembre 2026'!$G$343+'Detalle Compras Septiembre 2026'!$G$354+'Detalle Compras Septiembre 2026'!$G$603+'Detalle Compras Septiembre 2026'!$G$611+'Detalle Compras Septiembre 2026'!$G$617+'Detalle Compras Septiembre 2026'!$G$635+'Detalle Compras Septiembre 2026'!$G$696+'Detalle Compras Septiembre 2026'!$G$710 -> 718000 | F17: =IF($E$27>0, E17/$E$27, 0) -> 0.014425597 | G17: =IF(D17>0, E17/D17, 0) -> 65272.727 | I17: SUBTOTAL DÍA 7 (6 pagos) | N17: =SUM(N11:N16) -> 334000
B18: Turnos de Personal - Andrés | C18: Turno Operativo Salón/Apoyo | D18: 9 | E18: ='Detalle Compras Septiembre 2026'!$G$251+'Detalle Compras Septiembre 2026'!$G$314+'Detalle Compras Septiembre 2026'!$G$350+'Detalle Compras Septiembre 2026'!$G$387+'Detalle Compras Septiembre 2026'!$G$589+'Detalle Compras Septiembre 2026'!$G$604+'Detalle Compras Septiembre 2026'!$G$631+'Detalle Compras Septiembre 2026'!$G$690+'Detalle Compras Septiembre 2026'!$G$711 -> 594000 | F18: =IF($E$27>0, E18/$E$27, 0) -> 0.011934268 | G18: =IF(D18>0, E18/D18, 0) -> 66000 | I18: 8 | J18: Libro de Caja | K18: Andrés | L18: Turno Operativo | M18: Turno Andrés Principal (Johanna) | N18: ='Detalle Compras Septiembre 2026'!G251 -> 66000 | O18: Efectivo Caja Menor
B19: Turnos de Personal - Sebastián | C19: Turno Operativo Salón/Servicio | D19: 10 | E19: ='Detalle Compras Septiembre 2026'!$G$315+'Detalle Compras Septiembre 2026'!$G$351+'Detalle Compras Septiembre 2026'!$G$388+'Detalle Compras Septiembre 2026'!$G$591+'Detalle Compras Septiembre 2026'!$G$614+'Detalle Compras Septiembre 2026'!$G$630+'Detalle Compras Septiembre 2026'!$G$691+'Detalle Compras Septiembre 2026'!$G$697+'Detalle Compras Septiembre 2026'!$G$702+'Detalle Compras Septiembre 2026'!$G$712 -> 660000 | F19: =IF($E$27>0, E19/$E$27, 0) -> 0.013260298 | G19: =IF(D19>0, E19/D19, 0) -> 66000 | I19: 8 | J19: Libro de Caja | K19: Diego / Luigui | L19: Turno Operativo | M19: Turno Diego / Luigui Principal (Johanna) | N19: ='Detalle Compras Septiembre 2026'!G252 -> 66000 | O19: Efectivo Caja Menor
B20: Turnos de Personal - Wilson | C20: Turno Operativo Salón/Servicio | D20: 6 | E20: ='Detalle Compras Septiembre 2026'!$G$254+'Detalle Compras Septiembre 2026'!$G$389+'Detalle Compras Septiembre 2026'!$G$590+'Detalle Compras Septiembre 2026'!$G$689+'Detalle Compras Septiembre 2026'!$G$703+'Detalle Compras Septiembre 2026'!$G$713 -> 462000 | F20: =IF($E$27>0, E20/$E$27, 0) -> 0.0092822086 | G20: =IF(D20>0, E20/D20, 0) -> 77000 | I20: 8 | J20: Libro de Caja | K20: Marleny | L20: Turno Operativo | M20: Turno Marleny Domicilios (Neymar) | N20: ='Detalle Compras Septiembre 2026'!G253 -> 66000 | O20: Efectivo Caja Menor
B21: Seguridad y Vigilancia (Fredy Toty / Taty) | C21: Turno Nocturno / Vigilancia | D21: 2 | E21: ='Detalle Compras Septiembre 2026'!$G$352+'Detalle Compras Septiembre 2026'!$G$619 -> 140000 | F21: =IF($E$27>0, E21/$E$27, 0) -> 0.0028127905 | G21: =IF(D21>0, E21/D21, 0) -> 70000 | I21: 8 | J21: Libro de Caja | K21: Wilson | L21: Turno Operativo | M21: Wilson (Lunes y Martes) Principal (Johanna) - 2 días | N21: ='Detalle Compras Septiembre 2026'!G254 -> 132000 | O21: Efectivo Caja Menor
B22: Otros Turnos y Refuerzos Operativos | C22: Turnos y Horas Apoyo (Leyton/Martha/Lucero) | D22: 6 | E22: ='Detalle Compras Septiembre 2026'!$G$252+'Detalle Compras Septiembre 2026'!$G$414+'Detalle Compras Septiembre 2026'!$G$415+'Detalle Compras Septiembre 2026'!$G$618+'Detalle Compras Septiembre 2026'!$G$685+'Detalle Compras Septiembre 2026'!$G$706 -> 489200 | F22: =IF($E$27>0, E22/$E$27, 0) -> 0.0098286936 | G22: =IF(D22>0, E22/D22, 0) -> 81533.333 | I22: 8 | J22: Libro de Caja | K22: José David | L22: Vale Descontable | M22: Crédito José David Domicilios (Neymar) | N22: ='Detalle Compras Septiembre 2026'!G257 -> 20000 | O22: Anticipo Empleado
B23: Incentivos Laborales y Abonos | C23: Incentivo / Abono Cuenta Cobro | D23: 2 | E23: ='Detalle Compras Septiembre 2026'!$G$491+'Detalle Compras Septiembre 2026'!$G$492 -> 900000 | F23: =IF($E$27>0, E23/$E$27, 0) -> 0.018082225 | G23: =IF(D23>0, E23/D23, 0) -> 450000 | I23: SUBTOTAL DÍA 8 (5 pagos) | N23: =SUM(N18:N22) -> 350000
B24: Auxilio de Transporte de Personal | C24: Apoyo Transporte Operativo | D24: 10 | E24: ='Detalle Compras Septiembre 2026'!$G$195+'Detalle Compras Septiembre 2026'!$G$335+'Detalle Compras Septiembre 2026'!$G$347+'Detalle Compras Septiembre 2026'!$G$353+'Detalle Compras Septiembre 2026'!$G$379+'Detalle Compras Septiembre 2026'!$G$494+'Detalle Compras Septiembre 2026'!$G$698+'Detalle Compras Septiembre 2026'!$G$699+'Detalle Compras Septiembre 2026'!$G$700+'Detalle Compras Septiembre 2026'!$G$701 -> 305500 | F24: =IF($E$27>0, E24/$E$27, 0) -> 0.0061379107 | G24: =IF(D24>0, E24/D24, 0) -> 30550 | I24: 9 | J24: Libro de Caja | K24: Andrés | L24: Turno Operativo | M24: Turno Andrés Principal (Johanna) | N24: ='Detalle Compras Septiembre 2026'!G314 -> 66000 | O24: Efectivo Caja Menor
B25: Anticipos y Vales Empleados | C25: Préstamo Menor Descontable | D25: 7 | E25: ='Detalle Compras Septiembre 2026'!$G$193+'Detalle Compras Septiembre 2026'!$G$257+'Detalle Compras Septiembre 2026'!$G$593+'Detalle Compras Septiembre 2026'!$G$610+'Detalle Compras Septiembre 2026'!$G$707+'Detalle Compras Septiembre 2026'!$G$708+'Detalle Compras Septiembre 2026'!$G$709 -> 88800 | F25: =IF($E$27>0, E25/$E$27, 0) -> 0.0017841128 | G25: =IF(D25>0, E25/D25, 0) -> 12685.714 | I25: 9 | J25: Libro de Caja | K25: Sebastián | L25: Turno Operativo | M25: Turno Sebastián Principal (Johanna) | N25: ='Detalle Compras Septiembre 2026'!G315 -> 66000 | O25: Efectivo Caja Menor
B26: Salud Ocupacional y Exámenes Médicos (IPS) | C26: Exámenes Médicos Ingreso | D26: 6 | E26: =SUM('Detalle Compras Septiembre 2026'!$G$636:$G$641) -> 249500 | F26: =IF($E$27>0, E26/$E$27, 0) -> 0.0050127945 | G26: =IF(D26>0, E26/D26, 0) -> 41583.333 | I26: 9 | J26: Libro de Caja | K26: Marleny | L26: Turno Operativo | M26: Turno Marleny Domicilios (María) | N26: ='Detalle Compras Septiembre 2026'!G316 -> 66000 | O26: Efectivo Caja Menor
B27: TOTAL CONSOLIDADO TALENTO HUMANO Y HONORARIOS | C27: Todas las modalidades | D27: =SUM(D11:D26) -> 89 | E27: =SUM(E11:E26) -> 49772637 | F27: =SUM(F11:F26) -> 1 | G27: =IF(D27>0, E27/D27, 0) -> 559243.11 | I27: 9 | J27: Libro de Caja | K27: Arturo Díaz | L27: Gestión Directiva | M27: Don Arturo recogió Domicilios (María) | N27: ='Detalle Compras Septiembre 2026'!G318 -> 500000 | O27: Retiro Efectivo Caja
I28: SUBTOTAL DÍA 9 (4 pagos) | N28: =SUM(N24:N27) -> 698000
I29: 10 | J29: RCM-10-Sep-2026-7 | K29: Marleny | L29: Transporte Personal | M29: MARLENY - TRANSPORTE MAÑANA (Recibo Caja Menor) | N29: ='Detalle Compras Septiembre 2026'!G335 -> 20000 | O29: Apoyo Transporte
I30: 10 | J30: RCM-10-Sep-2026-5 | K30: Marleny | L30: Turno Operativo | M30: MARLENE - 7 HORAS (Recibo Caja Menor 10/09/2026) | N30: ='Detalle Compras Septiembre 2026'!G343 -> 58000 | O30: Recibo Oficial Caja
I31: 10 | J31: RCM-10-Sep-2026-4 | K31: Antonio Díaz | L31: Gestión Directiva | M31: ANTONIO L. DIAZ - TAXI DILIGENCIAS (Recibo Caja Menor) | N31: ='Detalle Compras Septiembre 2026'!G344 -> 10000 | O31: Recibo Oficial Caja
I32: 10 | J32: RCM-10-Sep-2026-1 | K32: Edith | L32: Transporte Personal | M32: TRANSPORTE EDITH (Recibo Caja Menor Marfil 10/09/26) | N32: ='Detalle Compras Septiembre 2026'!G347 -> 50000 | O32: Recibo Oficial Caja
I33: 10 | J33: Libro de Caja | K33: Andrés | L33: Turno Operativo | M33: Turno Andrés Principal (Johanna) | N33: ='Detalle Compras Septiembre 2026'!G350 -> 66000 | O33: Efectivo Caja Menor
I34: 10 | J34: Libro de Caja | K34: Sebastián | L34: Turno Operativo | M34: Turno Sebastián Principal (Johanna) | N34: ='Detalle Compras Septiembre 2026'!G351 -> 66000 | O34: Efectivo Caja Menor
I35: 10 | J35: Libro de Caja | K35: Taty Vigilancia | L35: Seguridad / Vigilancia | M35: Turno Taty Vigilancia Domicilios (Neymar) | N35: ='Detalle Compras Septiembre 2026'!G352 -> 70000 | O35: Efectivo Caja Menor
I36: 10 | J36: Libro de Caja | K36: Deys | L36: Transporte Personal | M36: Transporte Deys Domicilios (Neymar) | N36: ='Detalle Compras Septiembre 2026'!G353 -> 28000 | O36: Efectivo Caja Menor
I37: 10 | J37: Libro de Caja | K37: Marleny | L37: Turno Operativo | M37: Turno Marleny Domicilios (Neymar) | N37: ='Detalle Compras Septiembre 2026'!G354 -> 66000 | O37: Efectivo Caja Menor
I38: SUBTOTAL DÍA 10 (9 pagos) | N38: =SUM(N29:N37) -> 434000
I39: 11 | J39: Cuenta de Cobro | K39: Eliana | L39: Honorarios Operativos | M39: Pago de Servicios Eliana (Cuenta de Cobro) | N39: ='Detalle Compras Septiembre 2026'!G373 -> 1149000 | O39: Cuenta de Cobro
I40: 11 | J40: Cuaderno Don Arturo | K40: Contadora Pública | L40: Honorarios Contadora | M40: Honorarios Contadora (Cuaderno Don Arturo) | N40: ='Detalle Compras Septiembre 2026'!G374 -> 1200000 | O40: Asesoría Contable
I41: 11 | J41: FELE11955 | K41: GIT Organizacional | L41: Servicios Temporales | M41: SERVICIOS TEMPORALES + AIU (Factura FELE11955 - Agosto 16-31) | N41: ='Detalle Compras Septiembre 2026'!G377 -> 16523800 | O41: Factura Electrónica
I42: 11 | J42: Cuaderno Don Arturo | K42: Danilo | L42: Transporte Personal | M42: Transporte Danilo (Cuaderno Don Arturo) | N42: ='Detalle Compras Septiembre 2026'!G379 -> 15000 | O42: Apoyo Transporte
I43: 11 | J43: Libro de Caja | K43: Andrés | L43: Turno Operativo | M43: Turno Andrés Principal (Johanna/Wilson) | N43: ='Detalle Compras Septiembre 2026'!G387 -> 66000 | O43: Efectivo Caja Menor
...

Sheet Detalle Ventas Septiembre 2026
A1: Día | B1: Fecha | C1: Código | D1: Categoría | E1: Producto | F1: Unidad | G1: Cantidad Vendida | H1: Precio Unitario Neto | I1: Venta Bruta | J1: Descuentos | K1: Venta Neta | L1: Impoconsumo (8%) | M1: Gran Total Facturado | N1: % Part. Día | O1: Proveedor / Emisor Factura
A2: 1 | B2: 01/09/2026 | C2: 73 | D2: Bebidas | E2: Agua tarro | F2: ud | G2: 13 | H2: 2593 | I2: 33704 | J2: 0 | K2: 33704 | L2: 2696 | M2: 36400 | N2: 0.0054 | O2: Restaurante Choclos y Asados La Finca S.A.S.
A3: 1 | B3: 01/09/2026 | C3: 65 | D3: Bebidas | E3: Aguacate porc | F3: ud | G3: 2 | H3: 2778 | I3: 5556 | J3: 0 | K3: 5556 | L3: 444 | M3: 6000 | N3: 0.0009 | O3: Restaurante Choclos y Asados La Finca S.A.S.
A4: 1 | B4: 01/09/2026 | C4: 1 | D4: Platos Fuertes / Carnes | E4: Albondigas | F4: ud | G4: 22 | H4: 18729 | I4: 415741 | J4: 3704 | K4: 412037 | L4: 32963 | M4: 445000 | N4: 0.0656 | O4: Restaurante Choclos y Asados La Finca S.A.S.
A5: 1 | B5: 01/09/2026 | C5: 12 | D5: Pescados y Mariscos | E5: Arroz con camaron | F5: ud | G5: 7 | H5: 41667 | I5: 291667 | J5: 0 | K5: 291667 | L5: 23333 | M5: 315000 | N5: 0.0464 | O5: Restaurante Choclos y Asados La Finca S.A.S.
A6: 1 | B6: 01/09/2026 | C6: 104 | D6: Especialidades Típicas | E6: Bandeja sola | F6: ud | G6: 9 | H6: 15844 | I6: 144444 | J6: 1852 | K6: 142592 | L6: 11407 | M6: 153999 | N6: 0.0227 | O6: Restaurante Choclos y Asados La Finca S.A.S.
A7: 1 | B7: 01/09/2026 | C7: 95 | D7: Platos Fuertes / Carnes | E7: Bao | F7: ud | G7: 2 | H7: 926 | I7: 1852 | J7: 0 | K7: 1852 | L7: 148 | M7: 2000 | N7: 0.0003 | O7: Restaurante Choclos y Asados La Finca S.A.S.
A8: 1 | B8: 01/09/2026 | C8: 136 | D8: Especialidades Típicas | E8: Calentado chicharron | F8: ud | G8: 1 | H8: 24074 | I8: 24074 | J8: 0 | K8: 24074 | L8: 1926 | M8: 26000 | N8: 0.0038 | O8: Restaurante Choclos y Asados La Finca S.A.S.
A9: 1 | B9: 01/09/2026 | C9: 8 | D9: Platos Fuertes / Carnes | E9: Carne molida | F9: ud | G9: 11 | H9: 18855 | I9: 207407 | J9: 0 | K9: 207407 | L9: 16593 | M9: 224000 | N9: 0.033 | O9: Restaurante Choclos y Asados La Finca S.A.S.
A10: 1 | B10: 01/09/2026 | C10: 311 | D10: Pescados y Mariscos | E10: Cazuela de camaron | F10: ud | G10: 2 | H10: 44907 | I10: 89815 | J10: 0 | K10: 89815 | L10: 7185 | M10: 97000 | N10: 0.0143 | O10: Restaurante Choclos y Asados La Finca S.A.S.
A11: 1 | B11: 01/09/2026 | C11: 87 | D11: Especialidades Típicas | E11: Cazuela frijol | F11: ud | G11: 2 | H11: 37500 | I11: 75000 | J11: 0 | K11: 75000 | L11: 6000 | M11: 81000 | N11: 0.0119 | O11: Restaurante Choclos y Asados La Finca S.A.S.
A12: 1 | B12: 01/09/2026 | C12: 206 | D12: Pescados y Mariscos | E12: Cazuela mariscos | F12: ud | G12: 2 | H12: 44907 | I12: 89815 | J12: 0 | K12: 89815 | L12: 7185 | M12: 97000 | N12: 0.0143 | O12: Restaurante Choclos y Asados La Finca S.A.S.
A13: 1 | B13: 01/09/2026 | C13: 13 | D13: Platos Fuertes / Carnes | E13: Cerdo ejecutivo | F13: ud | G13: 2 | H13: 18519 | I13: 37037 | J13: 0 | K13: 37037 | L13: 2963 | M13: 40000 | N13: 0.0059 | O13: Restaurante Choclos y Asados La Finca S.A.S.
... A1598: 20 | B1598: 20/09/2026 | C1598: 1050 | D1598: Bebidas | E1598: Vive 100 pequ | F1598: ud | G1598: 0 | H1598: 0 | I1598: 0 | J1598: 0 | K1598: 0 | L1598: 0 | M1598: 0 | N1598: 0 | O1598: Restaurante Choclos y Asados La Finca S.A.S.

Sheet Detalle Compras Septiembre 2026
A1: Día | B1: Categoría | C1: Ítem | D1: Descripción Original (PDF) | E1: Cantidad | F1: Costo Unitario | G1: Vr. Compra | H1: N° Comprobante / Factura | I1: Relación con el Cuaderno | J1: Detalle | K1: Proveedor
A2: 1 | B2: Carnes | C2: Pezuña | D2: PEZUÑA CERDO A GRANEL (Supertiendas Cañaveral - 01FZ70896) | E2: 4.755 | F2: 7900 | G2: 37565 | H2: 01FZ70896 | I2: No Cruza con Cuaderno Don Arturo | K2: Supertiendas Cañaveral S.A.S.
A3: 1 | B3: Carnes | C3: Pezuña | D3: PEZUÑA CERDO A GRANEL (Supertiendas Cañaveral - 01FZ70896) | E3: 3.365 | F3: 8915.3 | G3: 30000 | H3: 01FZ70896 | I3: No Cruza con Cuaderno Don Arturo | K3: Supertiendas Cañaveral S.A.S.
A4: 1 | B4: Desechables | C4: Pilas | D4: PILA ALCALINA ENERGIZER (Supertiendas Cañaveral - 01FZ70896) | E4: 1 | F4: 14900 | G4: 14900 | H4: 01FZ70896 | I4: No Cruza con Cuaderno Don Arturo | K4: Supertiendas Cañaveral S.A.S.
A5: 1 | B5: Verduras | C5: Aguacate | D5: 8 AGUACATE COMUN*und (Supertiendas Cañaveral - 05FH119923) | E5: 8 | F5: 6800 | G5: 54400 | H5: 05FH119923 | I5: No Cruza con Cuaderno Don Arturo | K5: Supertiendas Cañaveral S.A.S.
A6: 1 | B6: Grano | C6: Arepas | D6: 100 arepas (Cuenta de Cobro 01-Sep-2026 Neftaly Ocampo) | E6: 100 | F6: 150 | G6: 15000 | H6: CC-01-Sep-2026 | I6: No Cruza con Cuaderno Don Arturo | K6: Neftaly Ocampo (Arepas)
A7: 1 | B7: Carnes | C7: Bagre de mar | D7: BAGRE DE MAR (Gabriel Ramirez Cubillos - FAC-188) | E7: 20 | F7: 16500 | G7: 330000 | H7: FAC-188 | I7: No Cruza con Cuaderno Don Arturo | K7: Alejandro Ramírez Cubillos (Pescados)
A8: 1 | B8: Carnes | C8: Filete de pollo x 120 | D8: Filete pollo 110g (Alexis Valencia - Factura 916) | E8: 4.58 | F8: 18500 | G8: 84730 | H8: FAC-916 | I8: No Cruza con Cuaderno Don Arturo | K8: Cárnicos Valencia (Alexis Valencia)
A9: 1 | B9: Carnes | C9: Filete de pollo x 350 | D9: Filete pollo 350g (Alexis Valencia - Factura 916) | E9: 15.1 | F9: 18500 | G9: 279350 | H9: FAC-916 | I9: Cruza con Cuaderno Don Arturo | K9: Cárnicos Valencia (Alexis Valencia)
A10: 1 | B10: Carnes | C10: Salmon | D10: Filete de Salmon Grande (Frio Sabor FVE-121) | E10: 9.87 | F10: 55000 | G10: 542850 | H10: FVE-121 | I10: No Cruza con Cuaderno Don Arturo | K10: Frío Sabor (Gerson Valencia)
A11: 1 | B11: Carnes | C11: Tilapia y truchas | D11: Tilapia Roja (Frio Sabor FVE-121) | E11: 19.81 | F11: 18000 | G11: 356580 | H11: FVE-121 | I11: No Cruza con Cuaderno Don Arturo | K11: Frío Sabor (Gerson Valencia)
A12: 1 | B12: INVENTARIO INICIAL | C12: INVENTARIO INICIAL | D12: INVENTARIO INICIAL | E12: 1 | F12: 12243950 | G12: 12243950 | H12: INVENTARIO INICIAL | I12: No Cruza con Cuaderno Don Arturo | K12: Inventario Inicial
A13: 1 | B13: Desechables | C13: Bloque media | D13: BLOQUE MEDIA (Hielo El Nevado NV202121) | E13: 2 | F13: 9500 | G13: 19000 | H13: NV202121 | I13: No Cruza con Cuaderno Don Arturo | K13: Industria Hielo El Nevado S.A.S.
... A27: 1 | B27: Carnes | C27: Tocino barril | D27: TOCINETA BARRIL (Carnes Los Monos - YP24152) | E27: 90.35 | F27: 21900 | G27: 1978665 | H27: YP24152 | I27: No Cruza con Cuaderno Don Arturo | K27: Distribuidora de Carnes ET Los Monos
A28: 1 | B28: Servicios Públicos | C28: Acueducto y Energía | D28: TOTAL A PAGAR | E28: 1 | F28: 921345 | G28: 921345 | H28: 18184113 | I28: No Cruza con Cuaderno Don Arturo | J28: 16/09/2026 | K28: EMCALI E.I.C.E. E.S.P.
A29: 2 | B29: Bebidas | C29: Gatorade | D29: BEB.GATORADE*500ml SURT. (Global Liquors - VC242401) | E29: 2 | F29: 39000 | G29: 78000 | H29: VC242401 | I29: No Cruza con Cuaderno Don Arturo | K29: Global Liquors (Licores)
A30: 2 | B30: Bebidas | C30: H2o | D30: AGUA H2O*600ml SURTIDA (Global Liquors VC242401 c/ NC NX8465) | E30: 1 | F30: 32500 | G30: 32500 | H30: VC242401 | I30: No Cruza con Cuaderno Don Arturo | K30: Global Liquors (Licores)
A31: 2 | B31: Bebidas | C31: Vive 100 | D31: BEB.EN.*380 VIVE100 (Global Liquors - VC242401) | E31: 1 | F31: 51600 | G31: 51600 | H31: VC242401 | I31: No Cruza con Cuaderno Don Arturo | K31: Global Liquors (Licores)
A32: 2 | B32: Desechables | C32: Bloque media | D32: BLOQUE MEDIA (Hielo El Nevado SF44886) | E32: 2 | F32: 9500 | G32: 19000 | H32: SF44886 | I32: No Cruza con Cuaderno Don Arturo | K32: Industria Hielo El Nevado S.A.S.
A33: 2 | B33: Verduras | C33: Aguacate | D33: 19 Aguacates (Recibo Caja Menor 02-Sep-2026) | E33: 19 | F33: 5263.16 | G33: 100000 | H33: RCM-02-Sep-2026 | I33: No Cruza con Cuaderno Don Arturo | K33: Gastos Menores / Caja Menor
A34: 2 | B34: Servicios | C34: Acopi | D34: Taxi - Acopi (Recibo Caja Menor 02-Sep-2026) | E34: 1 | F34: 30000 | G34: 30000 | H34: RCM-02-Sep-2026 | I34: No Cruza con Cuaderno Don Arturo | K34: Transporte Taxis / Acopi
A35: 2 | B35: Desechables | C35: Mazamorra | D35: Mazamorra (Franco Bravo - Recibo Caja Menor 02-Sep-2026) | E35: 1 | F35: 25000 | G35: 25000 | H35: RCM-02-Sep-2026 | I35: No Cruza con Cuaderno Don Arturo | K35: Gastos Menores / Caja Menor
A36: 2 | B36: Desechables | C36: Bloque media | D36: BLOQUE MEDIA (Hielo El Nevado - NV202202) | E36: 2 | F36: 9500 | G36: 19000 | H36: NV202202 | I36: No Cruza con Cuaderno Don Arturo | K36: Industria Hielo El Nevado S.A.S.
A37: 2 | B37: Desechables | C37: Bolsa 5kl tubular | D37: BOLSA X 5 KL TUBULAR (Hielo El Nevado - NV202202) | E37: 2 | F37: 5000 | G37: 10000 | H37: NV202202 | I37: No Cruza con Cuaderno Don Arturo | K37: Industria Hielo El Nevado S.A.S.
A38: 2 | B38: Grano | C38: Leche entera | D38: AVENA PRO CUBANA VASO 220G (Alquería - FEPL-3167991) | E38: 5 | F38: 3105.6 | G38: 15528 | H38: FEPL-3167991 | I38: Cruza con Cuaderno Don Arturo | K38: Productos Naturales de la Sabana (Alquería)
A39: 2 | B39: Grano | C39: Leche entera | D39: AVENA PRO AUTENTICA VASO 220G (Alquería - FEPL-3167991) | E39: 5 | F39: 3105.6 | G39: 15528 | H39: FEPL-3167991 | I39: Cruza con Cuaderno Don Arturo | K39: Productos Naturales de la Sabana (Alquería)
A40: 2 | B40: Grano | C40: Leche entera | D40: TANGELO BOTELLA 400 ML (Alquería - FEPL-3167991) | E40: 5 | F40: 1309 | G40: 6545 | H40: FEPL-3167991 | I40: Cruza con Cuaderno Don Arturo | K40: Productos Naturales de la Sabana (Alquería)
... A199: 7 | B199: Verduras | C199: Raices chinas | D199: 4 RAICES CHINAS VIVA MEJOR*250g (Supertiendas Cañaveral 11FH128829) | E199: 4 | F199: 2400 | G199: 9600 | H199: 11FH128829 | I199: No Cruza con Cuaderno Don Arturo | K199: Supertiendas Cañaveral S.A.S.
A200: 7 | B200: Insumos | C200: Arepas | D200: arepas | E200: 100 | F200: 150 | G200: 15000 | H200: S/N | I200: No Cruza con Cuaderno Don Arturo | J200: 16/09/2026 | K200: Neftaly Ocampo (Arepas)
A201: 8 | B201: Desechables | C201: Bolsa 5kl tubular | D201: BOLSA X 5 KL TUBULAR (Hielo El Nevado SF45044) | E201: 2 | F201: 5000 | G201: 10000 | H201: SF45044 | I201: No Cruza con Cuaderno Don Arturo | K201: Industria Hielo El Nevado S.A.S.
A202: 8 | B202: Verduras | C202: Arracacha | D202: Arracacha (Fruver Los Monos Remision A 0672) | E202: 4.2 | F202: 6000 | G202: 25200 | H202: REM-A 0672 | I202: No Cruza con Cuaderno Don Arturo | K202: Distribuidora de Carnes ET Los Monos
A203: 8 | B203: Verduras | C203: Arveja | D203: Arveja (Fruver Los Monos Remision A 0672) | E203: 3.3 | F203: 15000 | G203: 49500 | H203: REM-A 0672 | I203: No Cruza con Cuaderno Don Arturo | K203: Distribuidora de Carnes ET Los Monos
A204: 8 | B204: Verduras | C204: Cebolla Larga Atado | D204: Ata Larga (Fruver Los Monos Remision A 0672) | E204: 10 | F204: 6000 | G204: 60000 | H204: REM-A 0672 | I204: No Cruza con Cuaderno Don Arturo | K204: Distribuidora de Carnes ET Los Monos
A205: 8 | B205: Verduras | C205: Cebolla cabezona | D205: Cebolla Cabezona (Fruver Los Monos Remision A 0672) | E205: 9.5 | F205: 3800 | G205: 36100 | H205: REM-A 0672 | I205: No Cruza con Cuaderno Don Arturo | K205: Distribuidora de Carnes ET Los Monos
A206: 8 | B206: Verduras | C206: Lechuga batavia | D206: L. Batavia (Fruver Los Monos Remision A 0672) | E206: 42 | F206: 2800 | G206: 117600 | H206: REM-A 0672 | I206: No Cruza con Cuaderno Don Arturo | K206: Distribuidora de Carnes ET Los Monos
A207: 8 | B207: Verduras | C207: Limon tahiti | D207: Limon T (Fruver Los Monos Remision A 0672) | E207: 63.2 | F207: 3400 | G207: 214880 | H207: REM-A 0672 | I207: No Cruza con Cuaderno Don Arturo | K207: Distribuidora de Carnes ET Los Monos
A208: 8 | B208: Verduras | C208: Papa Capira bulto | D208: Capira bulto (Fruver Los Monos Remision A 0672) | E208: 1 | F208: 130000 | G208: 130000 | H208: REM-A 0672 | I208: No Cruza con Cuaderno Don Arturo | K208: Distribuidora de Carnes ET Los Monos
